2014-07-09 01:15:04,528 Unit account update failure: faiyam@faiyamrahman.com, beatthestreak1

2014-07-09 01:15:04,529     p1, p2: None, None

2014-07-09 01:15:04,529 
Traceback (most recent call last):
  File "chooseplayers.py", line 101, in choosePlayers
    p1, p2 = funcDict[sN]['dist_func'](bot, eligiblePlayers)
  File "/Users/faiyamrahman/programming/Python/beatthestreakBots/distributionfunctions.py", line 26, in randDownRandPlayers
    bot.choose_players(p1=p1, p2=p2)
  File "/Users/faiyamrahman/programming/Python/beatthestreakBots/bot.py", line 102, in choose_players
    assert p1[2] in self.teams.keys()
AssertionError
2014-07-09 01:15:06,424 Unit account update failure: faiyam@faiyamrahman.com, beatthestreak1

2014-07-09 01:15:06,425     p1, p2: None, None

2014-07-09 01:15:06,425 
Traceback (most recent call last):
  File "chooseplayers.py", line 101, in choosePlayers
    p1, p2 = funcDict[sN]['dist_func'](bot, eligiblePlayers)
  File "/Users/faiyamrahman/programming/Python/beatthestreakBots/distributionfunctions.py", line 26, in randDownRandPlayers
    bot.choose_players(p1=p1, p2=p2)
  File "/Users/faiyamrahman/programming/Python/beatthestreakBots/bot.py", line 102, in choose_players
    assert p1[2] in self.teams.keys()
AssertionError
2014-07-09 01:15:08,179 Unit account update failure: faiyam@faiyamrahman.com, beatthestreak1

2014-07-09 01:15:08,180     p1, p2: None, None

2014-07-09 01:15:08,180 
Traceback (most recent call last):
  File "chooseplayers.py", line 101, in choosePlayers
    p1, p2 = funcDict[sN]['dist_func'](bot, eligiblePlayers)
  File "/Users/faiyamrahman/programming/Python/beatthestreakBots/distributionfunctions.py", line 26, in randDownRandPlayers
    bot.choose_players(p1=p1, p2=p2)
  File "/Users/faiyamrahman/programming/Python/beatthestreakBots/bot.py", line 102, in choose_players
    assert p1[2] in self.teams.keys()
AssertionError
2014-07-09 01:15:08,250 1 of 1 accounts failed

2014-07-09 01:15:08,250     U, P: faiyam@faiyamrahman.com, beatthestreak1

2014-07-09 01:48:44,644 Unit account update failure: fossil.williams.1140@faiyamrahman.com, beatthestreak1

2014-07-09 01:48:44,644     p1, p2: None, None

2014-07-09 01:48:44,644 tuple index out of range
Traceback (most recent call last):
  File "chooseplayers.py", line 130, in choosePlayers
    p1, p2 = funcDict[sN]['dist_func'](bot, eligiblePlayers)
  File "/Users/faiyamrahman/programming/Python/beatthestreakBots/distributionfunctions.py", line 17, in randDownRandPlayers
    p1 = random.choice(eligiblePlayers)
  File "/System/Library/Frameworks/Python.framework/Versions/2.7/lib/python2.7/random.py", line 274, in choice
    return seq[int(self.random() * len(seq))]  # raises IndexError if seq is empty
IndexError: tuple index out of range
2014-07-09 01:48:46,406 Unit account update failure: fossil.williams.1140@faiyamrahman.com, beatthestreak1

2014-07-09 01:48:46,406     p1, p2: None, None

2014-07-09 01:48:46,406 tuple index out of range
Traceback (most recent call last):
  File "chooseplayers.py", line 130, in choosePlayers
    p1, p2 = funcDict[sN]['dist_func'](bot, eligiblePlayers)
  File "/Users/faiyamrahman/programming/Python/beatthestreakBots/distributionfunctions.py", line 17, in randDownRandPlayers
    p1 = random.choice(eligiblePlayers)
  File "/System/Library/Frameworks/Python.framework/Versions/2.7/lib/python2.7/random.py", line 274, in choice
    return seq[int(self.random() * len(seq))]  # raises IndexError if seq is empty
IndexError: tuple index out of range
2014-07-09 01:48:49,217 Unit account update failure: fossil.williams.1140@faiyamrahman.com, beatthestreak1

2014-07-09 01:48:49,217     p1, p2: None, None

2014-07-09 01:48:49,217 tuple index out of range
Traceback (most recent call last):
  File "chooseplayers.py", line 130, in choosePlayers
    p1, p2 = funcDict[sN]['dist_func'](bot, eligiblePlayers)
  File "/Users/faiyamrahman/programming/Python/beatthestreakBots/distributionfunctions.py", line 17, in randDownRandPlayers
    p1 = random.choice(eligiblePlayers)
  File "/System/Library/Frameworks/Python.framework/Versions/2.7/lib/python2.7/random.py", line 274, in choice
    return seq[int(self.random() * len(seq))]  # raises IndexError if seq is empty
IndexError: tuple index out of range
2014-07-09 01:48:49,380 1 of 1 accounts failed

2014-07-09 01:48:49,380     U, P: fossil.williams.1140@faiyamrahman.com, beatthestreak1

2014-07-09 11:10:22,250 Unit account update failure: daft.earth.1870@faiyamrahman.com, beatthestreak1

2014-07-09 11:10:22,251     p1, p2: None, None

2014-07-09 11:10:22,251 Message: u'unknown error: Element is not clickable at point (915, 609). Other element would receive the click: <div class="wait-indicator" style="display: block;" id="spinner">...</div>\n  (Session info: chrome=35.0.1916.153)\n  (Driver info: chromedriver=2.9.248307,platform=Mac OS X 10.9.2 x86_64)' 
Traceback (most recent call last):
  File "chooseplayers.py", line 163, in choosePlayers
    p1, p2 = funcDict[sN]['dist_func'](bot, eligiblePlayers)
  File "/Users/faiyamrahman/programming/Python/beatthestreakBots/distributionfunctions.py", line 28, in randDownRandPlayers
    bot.choose_players(p1=p1, p2=p2)
  File "/Users/faiyamrahman/programming/Python/beatthestreakBots/bot.py", line 123, in choose_players
    self.__choose_single_player(p1)
  File "/Users/faiyamrahman/programming/Python/beatthestreakBots/bot.py", line 449, in __choose_single_player
    raise NoPlayerFoundException("Player {0} {1} on team {2}".format(
  File "/Users/faiyamrahman/programming/Python/beatthestreakBots/bvenv/lib/python2.7/site-packages/selenium/webdriver/remote/webelement.py", line 60, in click
    self._execute(Command.CLICK_ELEMENT)
  File "/Users/faiyamrahman/programming/Python/beatthestreakBots/bvenv/lib/python2.7/site-packages/selenium/webdriver/remote/webelement.py", line 370, in _execute
    return self._parent.execute(command, params)
  File "/Users/faiyamrahman/programming/Python/beatthestreakBots/bvenv/lib/python2.7/site-packages/selenium/webdriver/remote/webdriver.py", line 173, in execute
    self.error_handler.check_response(response)
  File "/Users/faiyamrahman/programming/Python/beatthestreakBots/bvenv/lib/python2.7/site-packages/selenium/webdriver/remote/errorhandler.py", line 164, in check_response
    raise exception_class(message, screen, stacktrace)
WebDriverException: Message: u'unknown error: Element is not clickable at point (915, 609). Other element would receive the click: <div class="wait-indicator" style="display: block;" id="spinner">...</div>\n  (Session info: chrome=35.0.1916.153)\n  (Driver info: chromedriver=2.9.248307,platform=Mac OS X 10.9.2 x86_64)' 
2014-07-09 11:14:34,040 Unit account update failure: bts.metro.1385@faiyamrahman.com, beatthestreak1

2014-07-09 11:14:34,041     p1, p2: None, None

2014-07-09 11:14:34,041 Message: u'unknown error: Element is not clickable at point (715, 594). Other element would receive the click: <div class="wait-indicator" style="display: block;" id="spinner">...</div>\n  (Session info: chrome=35.0.1916.153)\n  (Driver info: chromedriver=2.9.248307,platform=Mac OS X 10.9.2 x86_64)' 
Traceback (most recent call last):
  File "chooseplayers.py", line 163, in choosePlayers
    p1, p2 = funcDict[sN]['dist_func'](bot, eligiblePlayers)
  File "/Users/faiyamrahman/programming/Python/beatthestreakBots/distributionfunctions.py", line 28, in randDownRandPlayers
    bot.choose_players(p1=p1, p2=p2)
  File "/Users/faiyamrahman/programming/Python/beatthestreakBots/bot.py", line 120, in choose_players
    self._reset_selections()
  File "/Users/faiyamrahman/programming/Python/beatthestreakBots/bot.py", line 330, in _reset_selections
    removeButtons[0].click()
  File "/Users/faiyamrahman/programming/Python/beatthestreakBots/bvenv/lib/python2.7/site-packages/selenium/webdriver/remote/webelement.py", line 60, in click
    self._execute(Command.CLICK_ELEMENT)
  File "/Users/faiyamrahman/programming/Python/beatthestreakBots/bvenv/lib/python2.7/site-packages/selenium/webdriver/remote/webelement.py", line 370, in _execute
    return self._parent.execute(command, params)
  File "/Users/faiyamrahman/programming/Python/beatthestreakBots/bvenv/lib/python2.7/site-packages/selenium/webdriver/remote/webdriver.py", line 173, in execute
    self.error_handler.check_response(response)
  File "/Users/faiyamrahman/programming/Python/beatthestreakBots/bvenv/lib/python2.7/site-packages/selenium/webdriver/remote/errorhandler.py", line 164, in check_response
    raise exception_class(message, screen, stacktrace)
WebDriverException: Message: u'unknown error: Element is not clickable at point (715, 594). Other element would receive the click: <div class="wait-indicator" style="display: block;" id="spinner">...</div>\n  (Session info: chrome=35.0.1916.153)\n  (Driver info: chromedriver=2.9.248307,platform=Mac OS X 10.9.2 x86_64)' 
2014-07-09 11:15:40,718 Unit account update failure: williams.daft.1832@faiyamrahman.com, beatthestreak1

2014-07-09 11:15:40,719     p1, p2: None, None

2014-07-09 11:15:40,719 
Traceback (most recent call last):
  File "chooseplayers.py", line 163, in choosePlayers
    p1, p2 = funcDict[sN]['dist_func'](bot, eligiblePlayers)
  File "/Users/faiyamrahman/programming/Python/beatthestreakBots/distributionfunctions.py", line 28, in randDownRandPlayers
    bot.choose_players(p1=p1, p2=p2)
  File "/Users/faiyamrahman/programming/Python/beatthestreakBots/bot.py", line 130, in choose_players
    assert set(self._get_chosen_players()) == playerSet
AssertionError
2014-07-09 11:17:12,363 Unit account update failure: williams.daft.1832@faiyamrahman.com, beatthestreak1

2014-07-09 11:17:12,363     p1, p2: None, None

2014-07-09 11:17:12,363 Message: '' 
Traceback (most recent call last):
  File "chooseplayers.py", line 163, in choosePlayers
    p1, p2 = funcDict[sN]['dist_func'](bot, eligiblePlayers)
  File "/Users/faiyamrahman/programming/Python/beatthestreakBots/distributionfunctions.py", line 28, in randDownRandPlayers
    bot.choose_players(p1=p1, p2=p2)
  File "/Users/faiyamrahman/programming/Python/beatthestreakBots/bot.py", line 123, in choose_players
    self.__choose_single_player(p1)
  File "/Users/faiyamrahman/programming/Python/beatthestreakBots/bot.py", line 418, in __choose_single_player
    EC.presence_of_element_located((By.CLASS_NAME, team)))
  File "/Users/faiyamrahman/programming/Python/beatthestreakBots/bvenv/lib/python2.7/site-packages/selenium/webdriver/support/wait.py", line 71, in until
    raise TimeoutException(message)
TimeoutException: Message: '' 
